Workbook

Sheet Mode d'emploi
A1: PROVITRES-64 — CALENDRIER ÉDITORIAL SEO : 10 PAGES PAR JOUR
A2: 1307 pages et articles du 28/09/2026 au 05/02/2027 (19 semaines), 10 par jour, 70 par semaine. Site : www.nettoyage-vitres-bayonne.fr. Zone : Pays Basque et Sud Landes (233 communes).
A4: La stratégie en 4 règles
A5: 1. Une seule page forte par ville, qui vise tous les mots-clés : nettoyage, lavage, laveur, nettoyeur de vitres, fenêtres, vitrerie. Google les considère comme une même recherche : une page par synonyme se ferait concurrence à elle-même.
A6: 2. Les villages de moins de 1 000 habitants sont regroupés par secteur (même code postal) ou cités sur la page de la ville voisine (colonne « Communes à citer »). Les 233 communes sont couvertes.
A7: 3. Les pages différentes, ce sont les métiers : mairies, immeubles, vitres en hauteur, hôtels, commerces, bureaux, syndics, conciergeries, écoles… × ville. C'est là que se trouvent les clients B2B.
A8: 4. Les vitres en hauteur sont l'argument n°1 sur toutes les pages pros : perche à eau pure jusqu'à 13 m, nacelle, formation au travail en hauteur.
A10: Ordre de publication (B2B d'abord)
A11: 1 · Piliers B2B (sem. 1) : une page par métier, par service (hauteur, immeuble, nacelle, façade vitrée, verrière, entreprise de nettoyage de vitres, fenêtres, vitrerie…) et par intercommunalité (CA Pays Basque, Seignanx, MACS, Grand Dax, Orthe et Arrigans).
A12: 2 · Pages villes (sem. 1–3) : 90 villes de plus de 1 000 hab., par population décroissante, + 14 pages de secteur pour les villages. Les 18 pages « lavage-vitres-[ville] » déjà en ligne sont à OPTIMISER, pas à recréer.
A13: 3 · Pages pros par ville (sem. 3–4) : « Entreprise nettoyage vitres [ville] », villes de plus de 2 000 hab.
A14: 4 · Métier × ville (sem. 4–14) : « Nettoyage vitres mairie Anglet », « Nettoyage vitres immeuble Biarritz », « Nettoyage vitres en hauteur Bayonne »…
... A28: • Search Console limite les demandes d'indexation manuelles à une dizaine par jour : le rythme du plan colle à cette limite.

Sheet Tableau de bord
A1: TABLEAU DE BORD SEO
A3: Aujourd'hui | B3: =COUNTIF('Calendrier SEO'!$B$2:$B$1308,TODAY()) | C3: pages/articles prévus
A4: En retard | B4: =COUNTIFS('Calendrier SEO'!$B$2:$B$1308,"<"&TODAY(),'Calendrier SEO'!$Y$2:$Y$1308,"À créer")+COUNTIFS('Calendrier SEO'!$B$2:$B$1308,"<"&TODAY(),'Calendrier SEO'!$Y$2:$Y$1308,"Rédigée") | C4: non mis en ligne alors que la date est passée
A6: Par phase
A7: Phase | B7: Prévu | C7: En ligne | D7: Indexées | E7: % indexé
A8: 1 · Piliers B2B | B8: =COUNTIF('Calendrier SEO'!$F$2:$F$1308,$A8) | C8: =COUNTIFS('Calendrier SEO'!$F$2:$F$1308,$A8,'Calendrier SEO'!$Y$2:$Y$1308,"En ligne")+COUNTIFS('Calendrier SEO'!$F$2:$F$1308,$A8,'Calendrier SEO'!$Y$2:$Y$1308,"Indexation demandée")+COUNTIFS('Calendrier SEO'!$F$2:$F$1308,$A8,'Calendrier SEO'!$Y$2:$Y$1308,"Indexée")+COUNTIFS('Calendrier SEO'!$F$2:$F$1308,$A8,'Calendrier SEO'!$Y$2:$Y$1308,"Non indexée") | D8: =COUNTIFS('Calendrier SEO'!$F$2:$F$1308,$A8,'Calendrier SEO'!$Y$2:$Y$1308,"Indexée") | E8: =IFERROR(D8/B8,0)
A9: 2 · Pages villes (1 par ville) | B9: =COUNTIF('Calendrier SEO'!$F$2:$F$1308,$A9) | C9: =COUNTIFS('Calendrier SEO'!$F$2:$F$1308,$A9,'Calendrier SEO'!$Y$2:$Y$1308,"En ligne")+COUNTIFS('Calendrier SEO'!$F$2:$F$1308,$A9,'Calendrier SEO'!$Y$2:$Y$1308,"Indexation demandée")+COUNTIFS('Calendrier SEO'!$F$2:$F$1308,$A9,'Calendrier SEO'!$Y$2:$Y$1308,"Indexée")+COUNTIFS('Calendrier SEO'!$F$2:$F$1308,$A9,'Calendrier SEO'!$Y$2:$Y$1308,"Non indexée") | D9: =COUNTIFS('Calendrier SEO'!$F$2:$F$1308,$A9,'Calendrier SEO'!$Y$2:$Y$1308,"Indexée") | E9: =IFERROR(D9/B9,0)
A10: 3 · Pages pros par ville | B10: =COUNTIF('Calendrier SEO'!$F$2:$F$1308,$A10) | C10: =COUNTIFS('Calendrier SEO'!$F$2:$F$1308,$A10,'Calendrier SEO'!$Y$2:$Y$1308,"En ligne")+COUNTIFS('Calendrier SEO'!$F$2:$F$1308,$A10,'Calendrier SEO'!$Y$2:$Y$1308,"Indexation demandée")+COUNTIFS('Calendrier SEO'!$F$2:$F$1308,$A10,'Calendrier SEO'!$Y$2:$Y$1308,"Indexée")+COUNTIFS('Calendrier SEO'!$F$2:$F$1308,$A10,'Calendrier SEO'!$Y$2:$Y$1308,"Non indexée") | D10: =COUNTIFS('Calendrier SEO'!$F$2:$F$1308,$A10,'Calendrier SEO'!$Y$2:$Y$1308,"Indexée") | E10: =IFERROR(D10/B10,0)
A11: 4 · Métier × ville | B11: =COUNTIF('Calendrier SEO'!$F$2:$F$1308,$A11) | C11: =COUNTIFS('Calendrier SEO'!$F$2:$F$1308,$A11,'Calendrier SEO'!$Y$2:$Y$1308,"En ligne")+COUNTIFS('Calendrier SEO'!$F$2:$F$1308,$A11,'Calendrier SEO'!$Y$2:$Y$1308,"Indexation demandée")+COUNTIFS('Calendrier SEO'!$F$2:$F$1308,$A11,'Calendrier SEO'!$Y$2:$Y$1308,"Indexée")+COUNTIFS('Calendrier SEO'!$F$2:$F$1308,$A11,'Calendrier SEO'!$Y$2:$Y$1308,"Non indexée") | D11: =COUNTIFS('Calendrier SEO'!$F$2:$F$1308,$A11,'Calendrier SEO'!$Y$2:$Y$1308,"Indexée") | E11: =IFERROR(D11/B11,0)
A12: 5 · Panneaux solaires × ville | B12: =COUNTIF('Calendrier SEO'!$F$2:$F$1308,$A12) | C12: =COUNTIFS('Calendrier SEO'!$F$2:$F$1308,$A12,'Calendrier SEO'!$Y$2:$Y$1308,"En ligne")+COUNTIFS('Calendrier SEO'!$F$2:$F$1308,$A12,'Calendrier SEO'!$Y$2:$Y$1308,"Indexation demandée")+COUNTIFS('Calendrier SEO'!$F$2:$F$1308,$A12,'Calendrier SEO'!$Y$2:$Y$1308,"Indexée")+COUNTIFS('Calendrier SEO'!$F$2:$F$1308,$A12,'Calendrier SEO'!$Y$2:$Y$1308,"Non indexée") | D12: =COUNTIFS('Calendrier SEO'!$F$2:$F$1308,$A12,'Calendrier SEO'!$Y$2:$Y$1308,"Indexée") | E12: =IFERROR(D12/B12,0)
A13: 6 · Particuliers | B13: =COUNTIF('Calendrier SEO'!$F$2:$F$1308,$A13) | C13: =COUNTIFS('Calendrier SEO'!$F$2:$F$1308,$A13,'Calendrier SEO'!$Y$2:$Y$1308,"En ligne")+COUNTIFS('Calendrier SEO'!$F$2:$F$1308,$A13,'Calendrier SEO'!$Y$2:$Y$1308,"Indexation demandée")+COUNTIFS('Calendrier SEO'!$F$2:$F$1308,$A13,'Calendrier SEO'!$Y$2:$Y$1308,"Indexée")+COUNTIFS('Calendrier SEO'!$F$2:$F$1308,$A13,'Calendrier SEO'!$Y$2:$Y$1308,"Non indexée") | D13: =COUNTIFS('Calendrier SEO'!$F$2:$F$1308,$A13,'Calendrier SEO'!$Y$2:$Y$1308,"Indexée") | E13: =IFERROR(D13/B13,0)
A14: Articles | B14: =COUNTIF('Calendrier SEO'!$F$2:$F$1308,$A14) | C14: =COUNTIFS('Calendrier SEO'!$F$2:$F$1308,$A14,'Calendrier SEO'!$Y$2:$Y$1308,"En ligne")+COUNTIFS('Calendrier SEO'!$F$2:$F$1308,$A14,'Calendrier SEO'!$Y$2:$Y$1308,"Indexation demandée")+COUNTIFS('Calendrier SEO'!$F$2:$F$1308,$A14,'Calendrier SEO'!$Y$2:$Y$1308,"Indexée")+COUNTIFS('Calendrier SEO'!$F$2:$F$1308,$A14,'Calendrier SEO'!$Y$2:$Y$1308,"Non indexée") | D14: =COUNTIFS('Calendrier SEO'!$F$2:$F$1308,$A14,'Calendrier SEO'!$Y$2:$Y$1308,"Indexée") | E14: =IFERROR(D14/B14,0)
A15: TOTAL | B15: =SUM(B8:B14) | C15: =SUM(C8:C14) | D15: =SUM(D8:D14) | E15: =IFERROR(D15/B15,0)
A17: Par semaine
A18: Semaine | B18: Du | C18: Prévu | D18: En ligne | E18: Indexées | F18: % en ligne
A19: S01 | B19: 46293 | C19: =COUNTIF('Calendrier SEO'!$D$2:$D$1308,$A19) | D19: =COUNTIFS('Calendrier SEO'!$D$2:$D$1308,$A19,'Calendrier SEO'!$Y$2:$Y$1308,"En ligne")+COUNTIFS('Calendrier SEO'!$D$2:$D$1308,$A19,'Calendrier SEO'!$Y$2:$Y$1308,"Indexation demandée")+COUNTIFS('Calendrier SEO'!$D$2:$D$1308,$A19,'Calendrier SEO'!$Y$2:$Y$1308,"Indexée")+COUNTIFS('Calendrier SEO'!$D$2:$D$1308,$A19,'Calendrier SEO'!$Y$2:$Y$1308,"Non indexée") | E19: =COUNTIFS('Calendrier SEO'!$D$2:$D$1308,$A19,'Calendrier SEO'!$Y$2:$Y$1308,"Indexée") | F19: =IFERROR(D19/C19,0)
A20: S02 | B20: 46300 | C20: =COUNTIF('Calendrier SEO'!$D$2:$D$1308,$A20) | D20: =COUNTIFS('Calendrier SEO'!$D$2:$D$1308,$A20,'Calendrier SEO'!$Y$2:$Y$1308,"En ligne")+COUNTIFS('Calendrier SEO'!$D$2:$D$1308,$A20,'Calendrier SEO'!$Y$2:$Y$1308,"Indexation demandée")+COUNTIFS('Calendrier SEO'!$D$2:$D$1308,$A20,'Calendrier SEO'!$Y$2:$Y$1308,"Indexée")+COUNTIFS('Calendrier SEO'!$D$2:$D$1308,$A20,'Calendrier SEO'!$Y$2:$Y$1308,"Non indexée") | E20: =COUNTIFS('Calendrier SEO'!$D$2:$D$1308,$A20,'Calendrier SEO'!$Y$2:$Y$1308,"Indexée") | F20: =IFERROR(D20/C20,0)
A21: S03 | B21: 46307 | C21: =COUNTIF('Calendrier SEO'!$D$2:$D$1308,$A21) | D21: =COUNTIFS('Calendrier SEO'!$D$2:$D$1308,$A21,'Calendrier SEO'!$Y$2:$Y$1308,"En ligne")+COUNTIFS('Calendrier SEO'!$D$2:$D$1308,$A21,'Calendrier SEO'!$Y$2:$Y$1308,"Indexation demandée")+COUNTIFS('Calendrier SEO'!$D$2:$D$1308,$A21,'Calendrier SEO'!$Y$2:$Y$1308,"Indexée")+COUNTIFS('Calendrier SEO'!$D$2:$D$1308,$A21,'Calendrier SEO'!$Y$2:$Y$1308,"Non indexée") | E21: =COUNTIFS('Calendrier SEO'!$D$2:$D$1308,$A21,'Calendrier SEO'!$Y$2:$Y$1308,"Indexée") | F21: =IFERROR(D21/C21,0)
A22: S04 | B22: 46314 | C22: =COUNTIF('Calendrier SEO'!$D$2:$D$1308,$A22) | D22: =COUNTIFS('Calendrier SEO'!$D$2:$D$1308,$A22,'Calendrier SEO'!$Y$2:$Y$1308,"En ligne")+COUNTIFS('Calendrier SEO'!$D$2:$D$1308,$A22,'Calendrier SEO'!$Y$2:$Y$1308,"Indexation demandée")+COUNTIFS('Calendrier SEO'!$D$2:$D$1308,$A22,'Calendrier SEO'!$Y$2:$Y$1308,"Indexée")+COUNTIFS('Calendrier SEO'!$D$2:$D$1308,$A22,'Calendrier SEO'!$Y$2:$Y$1308,"Non indexée") | E22: =COUNTIFS('Calendrier SEO'!$D$2:$D$1308,$A22,'Calendrier SEO'!$Y$2:$Y$1308,"Indexée") | F22: =IFERROR(D22/C22,0)
A23: S05 | B23: 46321 | C23: =COUNTIF('Calendrier SEO'!$D$2:$D$1308,$A23) | D23: =COUNTIFS('Calendrier SEO'!$D$2:$D$1308,$A23,'Calendrier SEO'!$Y$2:$Y$1308,"En ligne")+COUNTIFS('Calendrier SEO'!$D$2:$D$1308,$A23,'Calendrier SEO'!$Y$2:$Y$1308,"Indexation demandée")+COUNTIFS('Calendrier SEO'!$D$2:$D$1308,$A23,'Calendrier SEO'!$Y$2:$Y$1308,"Indexée")+COUNTIFS('Calendrier SEO'!$D$2:$D$1308,$A23,'Calendrier SEO'!$Y$2:$Y$1308,"Non indexée") | E23: =COUNTIFS('Calendrier SEO'!$D$2:$D$1308,$A23,'Calendrier SEO'!$Y$2:$Y$1308,"Indexée") | F23: =IFERROR(D23/C23,0)
A24: S06 | B24: 46328 | C24: =COUNTIF('Calendrier SEO'!$D$2:$D$1308,$A24) | D24: =COUNTIFS('Calendrier SEO'!$D$2:$D$1308,$A24,'Calendrier SEO'!$Y$2:$Y$1308,"En ligne")+COUNTIFS('Calendrier SEO'!$D$2:$D$1308,$A24,'Calendrier SEO'!$Y$2:$Y$1308,"Indexation demandée")+COUNTIFS('Calendrier SEO'!$D$2:$D$1308,$A24,'Calendrier SEO'!$Y$2:$Y$1308,"Indexée")+COUNTIFS('Calendrier SEO'!$D$2:$D$1308,$A24,'Calendrier SEO'!$Y$2:$Y$1308,"Non indexée") | E24: =COUNTIFS('Calendrier SEO'!$D$2:$D$1308,$A24,'Calendrier SEO'!$Y$2:$Y$1308,"Indexée") | F24: =IFERROR(D24/C24,0)
A25: S07 | B25: 46335 | C25: =COUNTIF('Calendrier SEO'!$D$2:$D$1308,$A25) | D25: =COUNTIFS('Calendrier SEO'!$D$2:$D$1308,$A25,'Calendrier SEO'!$Y$2:$Y$1308,"En ligne")+COUNTIFS('Calendrier SEO'!$D$2:$D$1308,$A25,'Calendrier SEO'!$Y$2:$Y$1308,"Indexation demandée")+COUNTIFS('Calendrier SEO'!$D$2:$D$1308,$A25,'Calendrier SEO'!$Y$2:$Y$1308,"Indexée")+COUNTIFS('Calendrier SEO'!$D$2:$D$1308,$A25,'Calendrier SEO'!$Y$2:$Y$1308,"Non indexée") | E25: =COUNTIFS('Calendrier SEO'!$D$2:$D$1308,$A25,'Calendrier SEO'!$Y$2:$Y$1308,"Indexée") | F25: =IFERROR(D25/C25,0)
A26: S08 | B26: 46342 | C26: =COUNTIF('Calendrier SEO'!$D$2:$D$1308,$A26) | D26: =COUNTIFS('Calendrier SEO'!$D$2:$D$1308,$A26,'Calendrier SEO'!$Y$2:$Y$1308,"En ligne")+COUNTIFS('Calendrier SEO'!$D$2:$D$1308,$A26,'Calendrier SEO'!$Y$2:$Y$1308,"Indexation demandée")+COUNTIFS('Calendrier SEO'!$D$2:$D$1308,$A26,'Calendrier SEO'!$Y$2:$Y$1308,"Indexée")+COUNTIFS('Calendrier SEO'!$D$2:$D$1308,$A26,'Calendrier SEO'!$Y$2:$Y$1308,"Non indexée") | E26: =COUNTIFS('Calendrier SEO'!$D$2:$D$1308,$A26,'Calendrier SEO'!$Y$2:$Y$1308,"Indexée") | F26: =IFERROR(D26/C26,0)
A27: S09 | B27: 46349 | C27: =COUNTIF('Calendrier SEO'!$D$2:$D$1308,$A27) | D27: =COUNTIFS('Calendrier SEO'!$D$2:$D$1308,$A27,'Calendrier SEO'!$Y$2:$Y$1308,"En ligne")+COUNTIFS('Calendrier SEO'!$D$2:$D$1308,$A27,'Calendrier SEO'!$Y$2:$Y$1308,"Indexation demandée")+COUNTIFS('Calendrier SEO'!$D$2:$D$1308,$A27,'Calendrier SEO'!$Y$2:$Y$1308,"Indexée")+COUNTIFS('Calendrier SEO'!$D$2:$D$1308,$A27,'Calendrier SEO'!$Y$2:$Y$1308,"Non indexée") | E27: =COUNTIFS('Calendrier SEO'!$D$2:$D$1308,$A27,'Calendrier SEO'!$Y$2:$Y$1308,"Indexée") | F27: =IFERROR(D27/C27,0)
A28: S10 | B28: 46356 | C28: =COUNTIF('Calendrier SEO'!$D$2:$D$1308,$A28) | D28: =COUNTIFS('Calendrier SEO'!$D$2:$D$1308,$A28,'Calendrier SEO'!$Y$2:$Y$1308,"En ligne")+COUNTIFS('Calendrier SEO'!$D$2:$D$1308,$A28,'Calendrier SEO'!$Y$2:$Y$1308,"Indexation demandée")+COUNTIFS('Calendrier SEO'!$D$2:$D$1308,$A28,'Calendrier SEO'!$Y$2:$Y$1308,"Indexée")+COUNTIFS('Calendrier SEO'!$D$2:$D$1308,$A28,'Calendrier SEO'!$Y$2:$Y$1308,"Non indexée") | E28: =COUNTIFS('Calendrier SEO'!$D$2:$D$1308,$A28,'Calendrier SEO'!$Y$2:$Y$1308,"Indexée") | F28: =IFERROR(D28/C28,0)
A29: S11 | B29: 46363 | C29: =COUNTIF('Calendrier SEO'!$D$2:$D$1308,$A29) | D29: =COUNTIFS('Calendrier SEO'!$D$2:$D$1308,$A29,'Calendrier SEO'!$Y$2:$Y$1308,"En ligne")+COUNTIFS('Calendrier SEO'!$D$2:$D$1308,$A29,'Calendrier SEO'!$Y$2:$Y$1308,"Indexation demandée")+COUNTIFS('Calendrier SEO'!$D$2:$D$1308,$A29,'Calendrier SEO'!$Y$2:$Y$1308,"Indexée")+COUNTIFS('Calendrier SEO'!$D$2:$D$1308,$A29,'Calendrier SEO'!$Y$2:$Y$1308,"Non indexée") | E29: =COUNTIFS('Calendrier SEO'!$D$2:$D$1308,$A29,'Calendrier SEO'!$Y$2:$Y$1308,"Indexée") | F29: =IFERROR(D29/C29,0)
A30: S12 | B30: 46370 | C30: =COUNTIF('Calendrier SEO'!$D$2:$D$1308,$A30) | D30: =COUNTIFS('Calendrier SEO'!$D$2:$D$1308,$A30,'Calendrier SEO'!$Y$2:$Y$1308,"En ligne")+COUNTIFS('Calendrier SEO'!$D$2:$D$1308,$A30,'Calendrier SEO'!$Y$2:$Y$1308,"Indexation demandée")+COUNTIFS('Calendrier SEO'!$D$2:$D$1308,$A30,'Calendrier SEO'!$Y$2:$Y$1308,"Indexée")+COUNTIFS('Calendrier SEO'!$D$2:$D$1308,$A30,'Calendrier SEO'!$Y$2:$Y$1308,"Non indexée") | E30: =COUNTIFS('Calendrier SEO'!$D$2:$D$1308,$A30,'Calendrier SEO'!$Y$2:$Y$1308,"Indexée") | F30: =IFERROR(D30/C30,0)
... A37: S19 | B37: 46419 | C37: =COUNTIF('Calendrier SEO'!$D$2:$D$1308,$A37) | D37: =COUNTIFS('Calendrier SEO'!$D$2:$D$1308,$A37,'Calendrier SEO'!$Y$2:$Y$1308,"En ligne")+COUNTIFS('Calendrier SEO'!$D$2:$D$1308,$A37,'Calendrier SEO'!$Y$2:$Y$1308,"Indexation demandée")+COUNTIFS('Calendrier SEO'!$D$2:$D$1308,$A37,'Calendrier SEO'!$Y$2:$Y$1308,"Indexée")+COUNTIFS('Calendrier SEO'!$D$2:$D$1308,$A37,'Calendrier SEO'!$Y$2:$Y$1308,"Non indexée") | E37: =COUNTIFS('Calendrier SEO'!$D$2:$D$1308,$A37,'Calendrier SEO'!$Y$2:$Y$1308,"Indexée") | F37: =IFERROR(D37/C37,0)

Sheet Calendrier SEO
A1: N° | B1: Date | C1: Jour | D1: Semaine | E1: Type | F1: Phase | G1: Cible | H1: Catégorie | I1: Ville | J1: Population | K1: Zone | L1: Segment / service | M1: Mot-clé principal | N1: Mots-clés secondaires | O1: Title SEO | P1: Meta description | Q1: H1 | R1: Plan H2 | S1: Angle local (contenu unique) | T1: Point fort à mettre en avant | U1: Communes à citer | V1: Slug (URL) | W1: URL complète | X1: Liens internes | Y1: Statut | Z1: Date mise en ligne | AA1: Indexation demandée le | AB1: Indexée ? | AC1: Notes
A2: 1 | B2: 46293 | C2: Lundi | D2: S01 | E2: Page hors menu | F2: 1 · Piliers B2B | G2: B2B | H2: Page pilier métier | L2: Mairies & bâtiments communaux | M2: Nettoyage vitres mairie Pays Basque | N2: lavage vitres mairie Landes, laveur de vitres mairies, nettoyeur de vitres professionnel | O2: Nettoyage vitres mairie Pays Basque & Sud Landes | P2: Nettoyage vitres mairie au Pays Basque et dans le Sud Landes pour vos bâtiments communaux : lavage à l'eau pure, vitres en hauteur jusqu'à 13 m, contrat… | Q2: Nettoyage vitres mairie au Pays Basque et dans le Sud Landes | R2: Pourquoi confier vos bâtiments communaux à un laveur de vitres pro | Ce que nous nettoyons | Vitres en hauteur : perche à eau pure jusqu'à 13 m, nacelle si besoin | Fréquence et contrat d'entretien | Villes desservies | Devis gratuit | T2: Devis par bâtiment, facturation Chorus Pro, interventions pendant les vacances scolaires | V2: nettoyage-vitres-mairie-pays-basque | W2: ="https://www.nettoyage-vitres-bayonne.fr/"&V2 | X2: service-de-nettoyage-professionnels, contact-devis | Y2: Rédigée | AC2: Page générée le 27/09/2026 — à mettre en ligne
A3: 2 | B3: 46293 | C3: Lundi | D3: S01 | E3: Page hors menu | F3: 1 · Piliers B2B | G3: B2B | H3: Page pilier métier | L3: Immeubles & copropriétés | M3: Nettoyage vitres immeuble Pays Basque | N3: lavage vitres immeuble Landes, laveur de vitres immeubles, nettoyeur de vitres professionnel | O3: Nettoyage vitres immeuble Pays Basque & Sud Landes | P3: Nettoyage vitres immeuble au Pays Basque et dans le Sud Landes pour votre immeuble : lavage à l'eau pure, vitres en hauteur jusqu'à 13 m, contrat sur… | Q3: Nettoyage vitres immeuble au Pays Basque et dans le Sud Landes | R3: Pourquoi confier votre immeuble à un laveur de vitres pro | Ce que nous nettoyons | Vitres en hauteur : perche à eau pure jusqu'à 13 m, nacelle si besoin | Fréquence et contrat d'entretien | Villes desservies | Devis gratuit | T3: Façades et parties communes en hauteur sans nacelle (perche 13 m), facture par immeuble pour les syndics | V3: nettoyage-vitres-immeuble-pays-basque | W3: ="https://www.nettoyage-vitres-bayonne.fr/"&V3 | X3: service-de-nettoyage-professionnels, contact-devis | Y3: Rédigée | AC3: Page générée le 27/09/2026 — à mettre en ligne
A4: 3 | B4: 46293 | C4: Lundi | D4: S01 | E4: Page hors menu | F4: 1 · Piliers B2B | G4: B2B | H4: Page pilier métier | L4: Vitres en hauteur | M4: Nettoyage vitres en hauteur Pays Basque | N4: lavage vitres en hauteur Landes, laveur de vitres vitres, nettoyeur de vitres professionnel | O4: Nettoyage vitres en hauteur Pays Basque & Sud Landes | P4: Nettoyage vitres en hauteur au Pays Basque et dans le Sud Landes pour vos vitres en hauteur : lavage à l'eau pure, vitres en hauteur jusqu'à 13 m, contrat… | Q4: Nettoyage vitres en hauteur au Pays Basque et dans le Sud Landes | R4: Pourquoi confier vos vitres en hauteur à un laveur de vitres pro | Ce que nous nettoyons | Vitres en hauteur : perche à eau pure jusqu'à 13 m, nacelle si besoin | Fréquence et contrat d'entretien | Villes desservies | Devis gratuit | T4: Perche télescopique eau pure 13 m, nacelle, formation travail en hauteur | V4: nettoyage-vitres-en-hauteur-pays-basque | W4: ="https://www.nettoyage-vitres-bayonne.fr/"&V4 | X4: service-de-nettoyage-professionnels, contact-devis | Y4: Rédigée | AC4: Page générée le 27/09/2026 — à mettre en ligne
A5: 4 | B5: 46293 | C5: Lundi | D5: S01 | E5: Page hors menu | F5: 1 · Piliers B2B | G5: B2B | H5: Page pilier métier | L5: Commerces & boutiques | M5: Nettoyage vitrine magasin Pays Basque | N5: lavage vitrine magasin Landes, laveur de vitres commerces, nettoyeur de vitres professionnel | O5: Nettoyage vitrine magasin Pays Basque & Sud Landes | P5: Nettoyage vitrine magasin au Pays Basque et dans le Sud Landes pour votre commerce : lavage à l'eau pure, vitres en hauteur jusqu'à 13 m, contrat sur… | Q5: Nettoyage vitrine magasin au Pays Basque et dans le Sud Landes | R5: Pourquoi confier votre commerce à un laveur de vitres pro | Ce que nous nettoyons | Vitres en hauteur : perche à eau pure jusqu'à 13 m, nacelle si besoin | Fréquence et contrat d'entretien | Villes desservies | Devis gratuit | T5: Passage avant l'ouverture, abonnement vitrine, tournée à vélo | V5: nettoyage-vitrine-magasin-pays-basque | W5: ="https://www.nettoyage-vitres-bayonne.fr/"&V5 | X5: service-de-nettoyage-professionnels, contact-devis | Y5: Rédigée | AC5: Page générée le 27/09/2026 — à mettre en ligne
A6: 5 | B6: 46293 | C6: Lundi | D6: S01 | E6: Page hors menu | F6: 1 · Piliers B2B | G6: B2B | H6: Page pilier métier | L6: Hôtels & résidences | M6: Nettoyage vitres hôtel Pays Basque | N6: lavage vitres hôtel Landes, laveur de vitres hôtels, nettoyeur de vitres professionnel | O6: Nettoyage vitres hôtel Pays Basque & Sud Landes | P6: Nettoyage vitres hôtel au Pays Basque et dans le Sud Landes pour votre hôtel : lavage à l'eau pure, vitres en hauteur jusqu'à 13 m, contrat sur mesure.… | Q6: Nettoyage vitres hôtel au Pays Basque et dans le Sud Landes | R6: Pourquoi confier votre hôtel à un laveur de vitres pro | Ce que nous nettoyons | Vitres en hauteur : perche à eau pure jusqu'à 13 m, nacelle si besoin | Fréquence et contrat d'entretien | Villes desservies | Devis gratuit | T6: Façades et baies des chambres en hauteur, interventions hors affluence, renfort avant la saison | V6: nettoyage-vitres-hotel-pays-basque | W6: ="https://www.nettoyage-vitres-bayonne.fr/"&V6 | X6: service-de-nettoyage-professionnels, contact-devis | Y6: Rédigée | AC6: Page générée le 27/09/2026 — à mettre en ligne
A7: 6 | B7: 46293 | C7: Lundi | D7: S01 | E7: Page hors menu | F7: 1 · Piliers B2B | G7: B2B | H7: Page pilier métier | L7: Bureaux & entreprises | M7: Nettoyage vitres bureaux Pays Basque | N7: lavage vitres bureaux Landes, laveur de vitres bureaux, nettoyeur de vitres professionnel | O7: Nettoyage vitres bureaux Pays Basque & Sud Landes | P7: Nettoyage vitres bureaux au Pays Basque et dans le Sud Landes pour vos bureaux : lavage à l'eau pure, vitres en hauteur jusqu'à 13 m, contrat sur mesure.… | Q7: Nettoyage vitres bureaux au Pays Basque et dans le Sud Landes | R7: Pourquoi confier vos bureaux à un laveur de vitres pro | Ce que nous nettoyons | Vitres en hauteur : perche à eau pure jusqu'à 13 m, nacelle si besoin | Fréquence et contrat d'entretien | Villes desservies | Devis gratuit | T7: Contrat d'entretien, interventions hors horaires, façades vitrées | V7: nettoyage-vitres-bureaux-pays-basque | W7: ="https://www.nettoyage-vitres-bayonne.fr/"&V7 | X7: service-de-nettoyage-professionnels, contact-devis | Y7: Rédigée | AC7: Page générée le 27/09/2026 — à mettre en ligne
A8: 7 | B8: 46293 | C8: Lundi | D8: S01 | E8: Page hors menu | F8: 1 · Piliers B2B | G8: B2B | H8: Page pilier métier | L8: Restaurants, bars & cafés | M8: Nettoyage vitres restaurant Pays Basque | N8: lavage vitres restaurant Landes, laveur de vitres restaurants,, nettoyeur de vitres professionnel | O8: Nettoyage vitres restaurant Pays Basque & Sud Landes | P8: Nettoyage vitres restaurant au Pays Basque et dans le Sud Landes pour votre restaurant : lavage à l'eau pure, vitres en hauteur jusqu'à 13 m, contrat sur… | Q8: Nettoyage vitres restaurant au Pays Basque et dans le Sud Landes | R8: Pourquoi confier votre restaurant à un laveur de vitres pro | Ce que nous nettoyons | Vitres en hauteur : perche à eau pure jusqu'à 13 m, nacelle si besoin | Fréquence et contrat d'entretien | Villes desservies | Devis gratuit | T8: Vitrine et terrasse vitrée propres avant le service | V8: nettoyage-vitres-restaurant-pays-basque | W8: ="https://www.nettoyage-vitres-bayonne.fr/"&V8 | X8: service-de-nettoyage-professionnels, contact-devis | Y8: Rédigée | AC8: Page générée le 27/09/2026 — à mettre en ligne
A9: 8 | B9: 46293 | C9: Lundi | D9: S01 | E9: Page hors menu | F9: 1 · Piliers B2B | G9: B2B | H9: Page pilier métier | L9: Conciergeries & locations saisonnières | M9: Nettoyage vitres location saisonnière Pays Basque | N9: lavage vitres location saisonnière Landes, laveur de vitres conciergeries, nettoyeur de vitres professionnel | O9: Nettoyage vitres location saisonnière Pays Basque & Sud Landes | P9: Nettoyage vitres location saisonnière au Pays Basque et dans le Sud Landes pour vos locations saisonnières : lavage à l'eau pure, vitres en hauteur… | Q9: Nettoyage vitres location saisonnière au Pays Basque et dans le Sud Landes | R9: Pourquoi confier vos locations saisonnières à un laveur de vitres pro | Ce que nous nettoyons | Vitres en hauteur : perche à eau pure jusqu'à 13 m, nacelle si besoin | Fréquence et contrat d'entretien | Villes desservies | Devis gratuit | T9: Passages entre deux séjours, baies vitrées face à la mer | V9: nettoyage-vitres-location-saisonniere-pays-basque | W9: ="https://www.nettoyage-vitres-bayonne.fr/"&V9 | X9: service-de-nettoyage-professionnels, contact-devis | Y9: Rédigée | AC9: Page générée le 27/09/2026 — à mettre en ligne
A10: 9 | B10: 46293 | C10: Lundi | D10: S01 | E10: Article | F10: Articles | G10: B2B | H10: Article vitres en hauteur / immeubles | L10: Vitres en hauteur | M10: nettoyage vitres en hauteur | O10: Nettoyage de vitres en hauteur : perche à eau pure ou | P10: Nettoyage de vitres en hauteur : perche à eau pure ou nacelle ? — les conseils de ProVitres-64, laveur de vitres professionnel au Pays Basque et dans le… | Q10: Nettoyage de vitres en hauteur : perche à eau pure ou nacelle ? | R10: Introduction | Le problème | Les solutions | Notre méthode | Conclusion + demande de devis | V10: blog-actus/nettoyage-de-vitres-en-hauteur-perche-a-eau-pure-ou-nacelle | W10: ="https://www.nettoyage-vitres-bayonne.fr/"&V10 | X10: blog-actus, contact-devis | Y10: Rédigée | AC10: Page générée le 27/09/2026 — à mettre en ligne
A11: 10 | B11: 46293 | C11: Lundi | D11: S01 | E11: Article | F11: Articles | G11: B2B | H11: Article vitres en hauteur / immeubles | L11: Vitres en hauteur | M11: nettoyage vitres en hauteur | O11: Comment on lave des vitres à 13 m sans nacelle | P11: Comment on lave des vitres à 13 m sans nacelle — les conseils de ProVitres-64, laveur de vitres professionnel au Pays Basque et dans le Sud Landes. | Q11: Comment on lave des vitres à 13 m sans nacelle | R11: Introduction | Le problème | Les solutions | Notre méthode | Conclusion + demande de devis | V11: blog-actus/comment-on-lave-des-vitres-a-13-m-sans-nacelle | W11: ="https://www.nettoyage-vitres-bayonne.fr/"&V11 | X11: blog-actus, contact-devis | Y11: Rédigée | AC11: Page générée le 27/09/2026 — à mettre en ligne
A12: 11 | B12: 46294 | C12: Mardi | D12: S01 | E12: Page hors menu | F12: 1 · Piliers B2B | G12: B2B | H12: Page pilier métier | L12: Écoles, collèges & crèches | M12: Nettoyage vitres école Pays Basque | N12: lavage vitres école Landes, laveur de vitres écoles,, nettoyeur de vitres professionnel | O12: Nettoyage vitres école Pays Basque & Sud Landes | P12: Nettoyage vitres école au Pays Basque et dans le Sud Landes pour votre établissement scolaire : lavage à l'eau pure, vitres en hauteur jusqu'à 13 m,… | Q12: Nettoyage vitres école au Pays Basque et dans le Sud Landes | R12: Pourquoi confier votre établissement scolaire à un laveur de vitres pro | Ce que nous nettoyons | Vitres en hauteur : perche à eau pure jusqu'à 13 m, nacelle si besoin | Fréquence et contrat d'entretien | Villes desservies | Devis gratuit | T12: Interventions pendant les vacances, verrières et préaux | V12: nettoyage-vitres-ecole-pays-basque | W12: ="https://www.nettoyage-vitres-bayonne.fr/"&V12 | X12: service-de-nettoyage-professionnels, contact-devis | Y12: Rédigée | AC12: Page générée le 27/09/2026 — à mettre en ligne
A13: 12 | B13: 46294 | C13: Mardi | D13: S01 | E13: Page hors menu | F13: 1 · Piliers B2B | G13: B2B | H13: Page pilier métier | L13: Agences immobilières | M13: Nettoyage vitres agence immobilière Pays Basque | N13: lavage vitres agence immobilière Landes, laveur de vitres agences, nettoyeur de vitres professionnel | O13: Nettoyage vitres agence immobilière Pays Basque & Sud Landes | P13: Nettoyage vitres agence immobilière au Pays Basque et dans le Sud Landes pour votre agence immobilière : lavage à l'eau pure, vitres en hauteur jusqu'à 13… | Q13: Nettoyage vitres agence immobilière au Pays Basque et dans le Sud Landes | R13: Pourquoi confier votre agence immobilière à un laveur de vitres pro | Ce que nous nettoyons | Vitres en hauteur : perche à eau pure jusqu'à 13 m, nacelle si besoin | Fréquence et contrat d'entretien | Villes desservies | Devis gratuit | T13: Vitres propres avant photos et visites, tarif partenaire | V13: nettoyage-vitres-agence-immobiliere-pays-basque | W13: ="https://www.nettoyage-vitres-bayonne.fr/"&V13 | X13: service-de-nettoyage-professionnels, contact-devis | Y13: Rédigée | AC13: Page générée le 27/09/2026 — à mettre en ligne
A14: 13 | B14: 46294 | C14: Mardi | D14: S01 | E14: Page hors menu | F14: 1 · Piliers B2B | G14: B2B | H14: Page pilier métier | L14: Cabinets médicaux & paramédicaux | M14: Nettoyage vitres cabinet médical Pays Basque | N14: lavage vitres cabinet médical Landes, laveur de vitres cabinets, nettoyeur de vitres professionnel | O14: Nettoyage vitres cabinet médical Pays Basque & Sud Landes | P14: Nettoyage vitres cabinet médical au Pays Basque et dans le Sud Landes pour votre cabinet : lavage à l'eau pure, vitres en hauteur jusqu'à 13 m, contrat… | Q14: Nettoyage vitres cabinet médical au Pays Basque et dans le Sud Landes | R14: Pourquoi confier votre cabinet à un laveur de vitres pro | Ce que nous nettoyons | Vitres en hauteur : perche à eau pure jusqu'à 13 m, nacelle si besoin | Fréquence et contrat d'entretien | Villes desservies | Devis gratuit | T14: Interventions hors consultations, image d'hygiène | V14: nettoyage-vitres-cabinet-medical-pays-basque | W14: ="https://www.nettoyage-vitres-bayonne.fr/"&V14 | X14: service-de-nettoyage-professionnels, contact-devis | Y14: Rédigée | AC14: Page générée le 27/09/2026 — à mettre en ligne
A15: 14 | B15: 46294 | C15: Mardi | D15: S01 | E15: Page hors menu | F15: 1 · Piliers B2B | G15: B2B | H15: Page pilier métier | L15: Fin de chantier | M15: Nettoyage vitres fin de chantier Pays Basque | N15: lavage vitres fin de chantier Landes, laveur de vitres fin, nettoyeur de vitres professionnel | O15: Nettoyage vitres fin de chantier Pays Basque & Sud Landes | P15: Nettoyage vitres fin de chantier au Pays Basque et dans le Sud Landes pour votre chantier : lavage à l'eau pure, vitres en hauteur jusqu'à 13 m, contrat… | Q15: Nettoyage vitres fin de chantier au Pays Basque et dans le Sud Landes | R15: Pourquoi confier votre chantier à un laveur de vitres pro | Ce que nous nettoyons | Vitres en hauteur : perche à eau pure jusqu'à 13 m, nacelle si besoin | Fréquence et contrat d'entretien | Villes desservies | Devis gratuit | T15: Ciment, peinture, silicone : décapage sans rayer | V15: nettoyage-vitres-fin-de-chantier-pays-basque | W15: ="https://www.nettoyage-vitres-bayonne.fr/"&V15 | X15: service-de-nettoyage-professionnels, contact-devis | Y15: Rédigée | AC15: Page générée le 27/09/2026 — à mettre en ligne
A16: 15 | B16: 46294 | C16: Mardi | D16: S01 | E16: Page hors menu | F16: 1 · Piliers B2B | G16: B2B | H16: Page pilier métier | L16: Supermarchés & grandes surfaces | M16: Nettoyage vitres supermarché Pays Basque | N16: lavage vitres supermarché Landes, laveur de vitres supermarchés, nettoyeur de vitres professionnel | O16: Nettoyage vitres supermarché Pays Basque & Sud Landes | P16: Nettoyage vitres supermarché au Pays Basque et dans le Sud Landes pour votre magasin : lavage à l'eau pure, vitres en hauteur jusqu'à 13 m, contrat sur… | Q16: Nettoyage vitres supermarché au Pays Basque et dans le Sud Landes | R16: Pourquoi confier votre magasin à un laveur de vitres pro | Ce que nous nettoyons | Vitres en hauteur : perche à eau pure jusqu'à 13 m, nacelle si besoin | Fréquence et contrat d'entretien | Villes desservies | Devis gratuit | T16: Grandes façades vitrées, interventions avant l'ouverture | V16: nettoyage-vitres-supermarche-pays-basque | W16: ="https://www.nettoyage-vitres-bayonne.fr/"&V16 | X16: service-de-nettoyage-professionnels, contact-devis | Y16: Rédigée | AC16: Page générée le 27/09/2026 — à mettre en ligne
A17: 16 | B17: 46294 | C17: Mardi | D17: S01 | E17: Page hors menu | F17: 1 · Piliers B2B | G17: B2B | H17: Page pilier métier | L17: EHPAD, cliniques & résidences seniors | M17: Nettoyage vitres EHPAD Pays Basque | N17: lavage vitres ehpad Landes, laveur de vitres ehpad,, nettoyeur de vitres professionnel | O17: Nettoyage vitres EHPAD Pays Basque & Sud Landes | P17: Nettoyage vitres EHPAD au Pays Basque et dans le Sud Landes pour votre établissement : lavage à l'eau pure, vitres en hauteur jusqu'à 13 m, contrat sur… | Q17: Nettoyage vitres EHPAD au Pays Basque et dans le Sud Landes | R17: Pourquoi confier votre établissement à un laveur de vitres pro | Ce que nous nettoyons | Vitres en hauteur : perche à eau pure jusqu'à 13 m, nacelle si besoin | Fréquence et contrat d'entretien | Villes desservies | Devis gratuit | T17: Interventions discrètes, sans produit chimique (eau pure) | V17: nettoyage-vitres-ehpad-pays-basque | W17: ="https://www.nettoyage-vitres-bayonne.fr/"&V17 | X17: service-de-nettoyage-professionnels, contact-devis | Y17: Rédigée | AC17: Page générée le 27/09/2026 — à mettre en ligne
A18: 17 | B18: 46294 | C18: Mardi | D18: S01 | E18: Page hors menu | F18: 1 · Piliers B2B | G18: B2B | H18: Page pilier métier | L18: Campings & résidences de tourisme | M18: Nettoyage vitres camping Pays Basque | N18: lavage vitres camping Landes, laveur de vitres campings, nettoyeur de vitres professionnel | O18: Nettoyage vitres camping Pays Basque & Sud Landes | P18: Nettoyage vitres camping au Pays Basque et dans le Sud Landes pour votre camping : lavage à l'eau pure, vitres en hauteur jusqu'à 13 m, contrat sur… | Q18: Nettoyage vitres camping au Pays Basque et dans le Sud Landes | R18: Pourquoi confier votre camping à un laveur de vitres pro | Ce que nous nettoyons | Vitres en hauteur : perche à eau pure jusqu'à 13 m, nacelle si besoin | Fréquence et contrat d'entretien | Villes desservies | Devis gratuit | T18: Grand nettoyage avant l'ouverture de la saison | V18: nettoyage-vitres-camping-pays-basque | W18: ="https://www.nettoyage-vitres-bayonne.fr/"&V18 | X18: service-de-nettoyage-professionnels, contact-devis | Y18: Rédigée | AC18: Page générée le 27/09/2026 — à mettre en ligne
A19: 18 | B19: 46294 | C19: Mardi | D19: S01 | E19: Page hors menu | F19: 1 · Piliers B2B | G19: B2B | H19: Page pilier métier | L19: Notaires, avocats & professions libérales | M19: Nettoyage vitres cabinet notaire Pays Basque | N19: lavage vitres cabinet notaire Landes, laveur de vitres notaires,, nettoyeur de vitres professionnel | O19: Nettoyage vitres cabinet notaire Pays Basque & Sud Landes | P19: Nettoyage vitres cabinet notaire au Pays Basque et dans le Sud Landes pour votre cabinet : lavage à l'eau pure, vitres en hauteur jusqu'à 13 m, contrat… | Q19: Nettoyage vitres cabinet notaire au Pays Basque et dans le Sud Landes | R19: Pourquoi confier votre cabinet à un laveur de vitres pro | Ce que nous nettoyons | Vitres en hauteur : perche à eau pure jusqu'à 13 m, nacelle si besoin | Fréquence et contrat d'entretien | Villes desservies | Devis gratuit | T19: Image soignée, interventions hors rendez-vous | V19: nettoyage-vitres-cabinet-notaire-pays-basque | W19: ="https://www.nettoyage-vitres-bayonne.fr/"&V19 | X19: service-de-nettoyage-professionnels, contact-devis | Y19: Rédigée | AC19: Page générée le 27/09/2026 — à mettre en ligne
A20: 19 | B20: 46294 | C20: Mardi | D20: S01 | E20: Article | F20: Articles | G20: B2B | H20: Article vitres en hauteur / immeubles | L20: Vitres en hauteur | M20: nettoyage vitres en hauteur | O20: Immeubles de la côte basque : l'entretien des vitres en | P20: Immeubles de la côte basque : l'entretien des vitres en façade — les conseils de ProVitres-64, laveur de vitres professionnel au Pays Basque et dans le… | Q20: Immeubles de la côte basque : l'entretien des vitres en façade | R20: Introduction | Le problème | Les solutions | Notre méthode | Conclusion + demande de devis | V20: blog-actus/immeubles-de-la-cote-basque-l-entretien-des-vitres-en-facade | W20: ="https://www.nettoyage-vitres-bayonne.fr/"&V20 | X20: blog-actus, contact-devis | Y20: Rédigée | AC20: Page générée le 27/09/2026 — à mettre en ligne
A21: 20 | B21: 46294 | C21: Mardi | D21: S01 | E21: Article | F21: Articles | G21: B2B | H21: Article vitres en hauteur / immeubles | L21: Vitres en hauteur | M21: nettoyage vitres en hauteur | O21: Vitres d'immeuble : qui paie, le syndic ou les | P21: Vitres d'immeuble : qui paie, le syndic ou les copropriétaires ? — les conseils de ProVitres-64, laveur de vitres professionnel au Pays Basque et dans le… | Q21: Vitres d'immeuble : qui paie, le syndic ou les copropriétaires ? | R21: Introduction | Le problème | Les solutions | Notre méthode | Conclusion + demande de devis | V21: blog-actus/vitres-d-immeuble-qui-paie-le-syndic-ou-les-coproprietaires | W21: ="https://www.nettoyage-vitres-bayonne.fr/"&V21 | X21: blog-actus, contact-devis | Y21: Rédigée | AC21: Page générée le 27/09/2026 — à mettre en ligne
A22: 21 | B22: 46295 | C22: Mercredi | D22: S01 | E22: Page hors menu | F22: 1 · Piliers B2B | G22: B2B | H22: Page pilier métier | L22: Pharmacies | M22: Nettoyage vitrine pharmacie Pays Basque | N22: lavage vitrine pharmacie Landes, laveur de vitres pharmacies, nettoyeur de vitres professionnel | O22: Nettoyage vitrine pharmacie Pays Basque & Sud Landes | P22: Nettoyage vitrine pharmacie au Pays Basque et dans le Sud Landes pour votre pharmacie : lavage à l'eau pure, vitres en hauteur jusqu'à 13 m, contrat sur… | Q22: Nettoyage vitrine pharmacie au Pays Basque et dans le Sud Landes | R22: Pourquoi confier votre pharmacie à un laveur de vitres pro | Ce que nous nettoyons | Vitres en hauteur : perche à eau pure jusqu'à 13 m, nacelle si besoin | Fréquence et contrat d'entretien | Villes desservies | Devis gratuit | T22: Vitrine et croix visibles, passage avant l'ouverture | V22: nettoyage-vitrine-pharmacie-pays-basque | W22: ="https://www.nettoyage-vitres-bayonne.fr/"&V22 | X22: service-de-nettoyage-professionnels, contact-devis | Y22: Rédigée | AC22: Page générée le 27/09/2026 — à mettre en ligne
A23: 22 | B23: 46295 | C23: Mercredi | D23: S01 | E23: Page hors menu | F23: 1 · Piliers B2B | G23: B2B | H23: Page pilier métier | L23: Banques & assurances | M23: Nettoyage vitres agence bancaire Pays Basque | N23: lavage vitres agence bancaire Landes, laveur de vitres banques, nettoyeur de vitres professionnel | O23: Nettoyage vitres agence bancaire Pays Basque & Sud Landes | P23: Nettoyage vitres agence bancaire au Pays Basque et dans le Sud Landes pour votre agence : lavage à l'eau pure, vitres en hauteur jusqu'à 13 m, contrat sur… | Q23: Nettoyage vitres agence bancaire au Pays Basque et dans le Sud Landes | R23: Pourquoi confier votre agence à un laveur de vitres pro | Ce que nous nettoyons | Vitres en hauteur : perche à eau pure jusqu'à 13 m, nacelle si besoin | Fréquence et contrat d'entretien | Villes desservies | Devis gratuit | T23: Contrat multi-agences | V23: nettoyage-vitres-agence-bancaire-pays-basque | W23: ="https://www.nettoyage-vitres-bayonne.fr/"&V23 | X23: service-de-nettoyage-professionnels, contact-devis | Y23: Rédigée | AC23: Page générée le 27/09/2026 — à mettre en ligne
A24: 23 | B24: 46295 | C24: Mercredi | D24: S01 | E24: Page hors menu | F24: 1 · Piliers B2B | G24: B2B | H24: Page pilier métier | L24: Concessions & loueurs de voitures | M24: Nettoyage vitres concession automobile Pays Basque | N24: lavage vitres concession automobile Landes, laveur de vitres concessions, nettoyeur de vitres professionnel | O24: Nettoyage vitres concession automobile Pays Basque & Sud Landes | P24: Nettoyage vitres concession automobile au Pays Basque et dans le Sud Landes pour votre showroom : lavage à l'eau pure, vitres en hauteur jusqu'à 13 m,… | Q24: Nettoyage vitres concession automobile au Pays Basque et dans le Sud Landes | R24: Pourquoi confier votre showroom à un laveur de vitres pro | Ce que nous nettoyons | Vitres en hauteur : perche à eau pure jusqu'à 13 m, nacelle si besoin | Fréquence et contrat d'entretien | Villes desservies | Devis gratuit | T24: Grands showrooms vitrés, façades hautes | V24: nettoyage-vitres-concession-automobile-pays-basque | W24: ="https://www.nettoyage-vitres-bayonne.fr/"&V24 | X24: service-de-nettoyage-professionnels, contact-devis | Y24: Rédigée | AC24: Page générée le 27/09/2026 — à mettre en ligne
A25: 24 | B25: 46295 | C25: Mercredi | D25: S01 | E25: Page hors menu | F25: 1 · Piliers B2B | G25: B2B | H25: Page pilier métier | L25: Salles de sport & loisirs | M25: Nettoyage vitres salle de sport Pays Basque | N25: lavage vitres salle de sport Landes, laveur de vitres salles, nettoyeur de vitres professionnel | O25: Nettoyage vitres salle de sport Pays Basque & Sud Landes | P25: Nettoyage vitres salle de sport au Pays Basque et dans le Sud Landes pour votre salle : lavage à l'eau pure, vitres en hauteur jusqu'à 13 m, contrat sur… | Q25: Nettoyage vitres salle de sport au Pays Basque et dans le Sud Landes | R25: Pourquoi confier votre salle à un laveur de vitres pro | Ce que nous nettoyons | Vitres en hauteur : perche à eau pure jusqu'à 13 m, nacelle si besoin | Fréquence et contrat d'entretien | Villes desservies | Devis gratuit | T25: Baies et miroirs sans traces | V25: nettoyage-vitres-salle-de-sport-pays-basque | W25: ="https://www.nettoyage-vitres-bayonne.fr/"&V25 | X25: service-de-nettoyage-professionnels, contact-devis | Y25: Rédigée | AC25: Page générée le 27/09/2026 — à mettre en ligne
A26: 25 | B26: 46295 | C26: Mercredi | D26: S01 | E26: Page hors menu | F26: 1 · Piliers B2B | G26: B2B | H26: Page pilier métier | L26: Instituts & salons de coiffure | M26: Nettoyage vitrine salon de coiffure Pays Basque | N26: lavage vitrine salon de coiffure Landes, laveur de vitres instituts, nettoyeur de vitres professionnel | O26: Nettoyage vitrine salon de coiffure Pays Basque & Sud Landes | P26: Nettoyage vitrine salon de coiffure au Pays Basque et dans le Sud Landes pour votre salon : lavage à l'eau pure, vitres en hauteur jusqu'à 13 m, contrat… | Q26: Nettoyage vitrine salon de coiffure au Pays Basque et dans le Sud Landes | R26: Pourquoi confier votre salon à un laveur de vitres pro | Ce que nous nettoyons | Vitres en hauteur : perche à eau pure jusqu'à 13 m, nacelle si besoin | Fréquence et contrat d'entretien | Villes desservies | Devis gratuit | T26: Vitrine et miroirs impeccables | V26: nettoyage-vitrine-salon-coiffure-pays-basque | W26: ="https://www.nettoyage-vitres-bayonne.fr/"&V26 | X26: service-de-nettoyage-professionnels, contact-devis | Y26: Rédigée | AC26: Page générée le 27/09/2026 — à mettre en ligne
A27: 26 | B27: 46295 | C27: Mercredi | D27: S01 | E27: Page hors menu | F27: 1 · Piliers B2B | G27: B2B | H27: Page pilier métier | L27: Locaux industriels & entrepôts | M27: Nettoyage vitres locaux industriels Pays Basque | N27: lavage vitres locaux industriels Landes, laveur de vitres locaux, nettoyeur de vitres professionnel | O27: Nettoyage vitres locaux industriels Pays Basque & Sud Landes | P27: Nettoyage vitres locaux industriels au Pays Basque et dans le Sud Landes pour vos locaux : lavage à l'eau pure, vitres en hauteur jusqu'à 13 m, contrat… | Q27: Nettoyage vitres locaux industriels au Pays Basque et dans le Sud Landes | R27: Pourquoi confier vos locaux à un laveur de vitres pro | Ce que nous nettoyons | Vitres en hauteur : perche à eau pure jusqu'à 13 m, nacelle si besoin | Fréquence et contrat d'entretien | Villes desservies | Devis gratuit | T27: Vitrages en hauteur, bardages translucides, sheds | V27: nettoyage-vitres-locaux-industriels-pays-basque | W27: ="https://www.nettoyage-vitres-bayonne.fr/"&V27 | X27: service-de-nettoyage-professionnels, contact-devis | Y27: Rédigée | AC27: Page générée le 27/09/2026 — à mettre en ligne
A28: 27 | B28: 46295 | C28: Mercredi | D28: S01 | E28: Page hors menu | F28: 1 · Piliers B2B | G28: B2B | H28: Page pilier métier | L28: Abribus, gares & transports | M28: Nettoyage abribus Pays Basque | N28: lavage abribus Landes, laveur de vitres abribus,, nettoyeur de vitres professionnel | O28: Nettoyage abribus Pays Basque & Sud Landes | ProVitres-64 | P28: Nettoyage abribus au Pays Basque et dans le Sud Landes pour vos abribus et gares : lavage à l'eau pure, vitres en hauteur jusqu'à 13 m, contrat sur… | Q28: Nettoyage abribus au Pays Basque et dans le Sud Landes | R28: Pourquoi confier vos abribus et gares à un laveur de vitres pro | Ce que nous nettoyons | Vitres en hauteur : perche à eau pure jusqu'à 13 m, nacelle si besoin | Fréquence et contrat d'entretien | Villes desservies | Devis gratuit | T28: Tournées planifiées, vitres anti-graffiti | V28: nettoyage-abribus-pays-basque | W28: ="https://www.nettoyage-vitres-bayonne.fr/"&V28 | X28: service-de-nettoyage-professionnels, contact-devis | Y28: Rédigée | AC28: Page générée le 27/09/2026 — à mettre en ligne
A29: 28 | B29: 46295 | C29: Mercredi | D29: S01 | E29: Page hors menu | F29: 1 · Piliers B2B | G29: B2B | H29: Page pilier métier | L29: Ports & capitaineries | M29: Nettoyage vitres port Pays Basque | N29: lavage vitres port Landes, laveur de vitres ports, nettoyeur de vitres professionnel | O29: Nettoyage vitres port Pays Basque & Sud Landes | P29: Nettoyage vitres port au Pays Basque et dans le Sud Landes pour vos locaux portuaires : lavage à l'eau pure, vitres en hauteur jusqu'à 13 m, contrat sur… | Q29: Nettoyage vitres port au Pays Basque et dans le Sud Landes | R29: Pourquoi confier vos locaux portuaires à un laveur de vitres pro | Ce que nous nettoyons | Vitres en hauteur : perche à eau pure jusqu'à 13 m, nacelle si besoin | Fréquence et contrat d'entretien | Villes desservies | Devis gratuit | T29: Sel et embruns : vitres de capitaineries, commerces du port | V29: nettoyage-vitres-port-pays-basque | W29: ="https://www.nettoyage-vitres-bayonne.fr/"&V29 | X29: service-de-nettoyage-professionnels, contact-devis | Y29: Rédigée | AC29: Page générée le 27/09/2026 — à mettre en ligne
A30: 29 | B30: 46295 | C30: Mercredi | D30: S01 | E30: Article | F30: Articles | G30: B2B | H30: Article vitres en hauteur / immeubles | L30: Vitres en hauteur | M30: nettoyage vitres en hauteur | O30: Travail en hauteur : les règles de sécurité d'un laveur de | P30: Travail en hauteur : les règles de sécurité d'un laveur de vitres — les conseils de ProVitres-64, laveur de vitres professionnel au Pays Basque et dans le… | Q30: Travail en hauteur : les règles de sécurité d'un laveur de vitres | R30: Introduction | Le problème | Les solutions | Notre méthode | Conclusion + demande de devis | V30: blog-actus/travail-en-hauteur-les-regles-de-securite-d-un-laveur-de-vitres | W30: ="https://www.nettoyage-vitres-bayonne.fr/"&V30 | X30: blog-actus, contact-devis | Y30: Rédigée | AC30: Page générée le 27/09/2026 — à mettre en ligne
A31: 30 | B31: 46295 | C31: Mercredi | D31: S01 | E31: Article | F31: Articles | G31: B2B | H31: Article vitres en hauteur / immeubles | L31: Vitres en hauteur | M31: nettoyage vitres en hauteur | O31: Façades vitrées : les entretenir sans échafaudage | P31: Façades vitrées : les entretenir sans échafaudage — les conseils de ProVitres-64, laveur de vitres professionnel au Pays Basque et dans le Sud Landes. | Q31: Façades vitrées : les entretenir sans échafaudage | R31: Introduction | Le problème | Les solutions | Notre méthode | Conclusion + demande de devis | V31: blog-actus/facades-vitrees-les-entretenir-sans-echafaudage | W31: ="https://www.nettoyage-vitres-bayonne.fr/"&V31 | X31: blog-actus, contact-devis | Y31: Rédigée | AC31: Page générée le 27/09/2026 — à mettre en ligne
A32: 31 | B32: 46296 | C32: Jeudi | D32: S01 | E32: Page hors menu | F32: 1 · Piliers B2B | G32: B2B | H32: Page pilier service | L32: Service | M32: Entreprise de nettoyage de vitres | N32: société nettoyage vitres, prestataire vitres, laveur de vitres professionnel | O32: Entreprise de nettoyage de vitres | ProVitres-64 | P32: Entreprise de nettoyage de vitres par ProVitres-64, laveur de vitres professionnel basé à Boucau : eau pure, perche 13 m, nacelle. Pays Basque et Sud… | Q32: Entreprise de nettoyage de vitres — ProVitres-64 | R32: Notre prestation | Pour qui ? | Vitres en hauteur : perche à eau pure jusqu'à 13 m, nacelle si besoin | Sécurité & travail en hauteur | Zones d'intervention | Devis gratuit | T32: Vitres en hauteur : perche à eau pure jusqu'à 13 m, nacelle si besoin | V32: entreprise-nettoyage-vitres-pays-basque | W32: ="https://www.nettoyage-vitres-bayonne.fr/"&V32 | X32: service-de-nettoyage-professionnels, contact-devis | Y32: Rédigée | AC32: Page générée le 27/09/2026 — à mettre en ligne
A33: 32 | B33: 46296 | C33: Jeudi | D33: S01 | E33: Page hors menu | F33: 1 · Piliers B2B | G33: B2B | H33: Page pilier service | L33: Service | M33: Nettoyage vitres en hauteur | N33: vitres difficiles d'accès, perche télescopique 13 m, sans nacelle, lavage vitres hauteur | O33: Nettoyage vitres en hauteur | ProVitres-64 | P33: Nettoyage vitres en hauteur par ProVitres-64, laveur de vitres professionnel basé à Boucau : eau pure, perche 13 m, nacelle. Pays Basque et Sud Landes.… | Q33: Nettoyage vitres en hauteur — ProVitres-64 | R33: Notre prestation | Pour qui ? | Vitres en hauteur : perche à eau pure jusqu'à 13 m, nacelle si besoin | Sécurité & travail en hauteur | Zones d'intervention | Devis gratuit | T33: Vitres en hauteur : perche à eau pure jusqu'à 13 m, nacelle si besoin | V33: nettoyage-vitres-hauteur-eau-pure | W33: ="https://www.nettoyage-vitres-bayonne.fr/"&V33 | X33: service-de-nettoyage-professionnels, contact-devis | Y33: Rédigée | AC33: Page générée le 27/09/2026 — à mettre en ligne
A34: 33 | B34: 46296 | C34: Jeudi | D34: S01 | E34: Page hors menu | F34: 1 · Piliers B2B | G34: B2B | H34: Page pilier service | L34: Service | M34: Nettoyage vitres par nacelle | N34: nacelle, travail en hauteur, vitres grande hauteur | O34: Nettoyage vitres par nacelle | ProVitres-64 | P34: Nettoyage vitres par nacelle par ProVitres-64, laveur de vitres professionnel basé à Boucau : eau pure, perche 13 m, nacelle. Pays Basque et Sud Landes.… | Q34: Nettoyage vitres par nacelle — ProVitres-64 | R34: Notre prestation | Pour qui ? | Vitres en hauteur : perche à eau pure jusqu'à 13 m, nacelle si besoin | Sécurité & travail en hauteur | Zones d'intervention | Devis gratuit | T34: Vitres en hauteur : perche à eau pure jusqu'à 13 m, nacelle si besoin | V34: nettoyage-vitres-nacelle-pays-basque | W34: ="https://www.nettoyage-vitres-bayonne.fr/"&V34 | X34: service-de-nettoyage-professionnels, contact-devis | Y34: Rédigée | AC34: Page générée le 27/09/2026 — à mettre en ligne
A35: 34 | B35: 46296 | C35: Jeudi | D35: S01 | E35: Page hors menu | F35: 1 · Piliers B2B | G35: B2B | H35: Page pilier service | L35: Service | M35: Nettoyage façade vitrée | N35: façade verre, mur rideau, vitrage extérieur immeuble | O35: Nettoyage façade vitrée | ProVitres-64 | P35: Nettoyage façade vitrée par ProVitres-64, laveur de vitres professionnel basé à Boucau : eau pure, perche 13 m, nacelle. Pays Basque et Sud Landes. Devis… | Q35: Nettoyage façade vitrée — ProVitres-64 | R35: Notre prestation | Pour qui ? | Vitres en hauteur : perche à eau pure jusqu'à 13 m, nacelle si besoin | Sécurité & travail en hauteur | Zones d'intervention | Devis gratuit | T35: Vitres en hauteur : perche à eau pure jusqu'à 13 m, nacelle si besoin | V35: nettoyage-facade-vitree-pays-basque | W35: ="https://www.nettoyage-vitres-bayonne.fr/"&V35 | X35: service-de-nettoyage-professionnels, contact-devis | Y35: Rédigée | AC35: Page générée le 27/09/2026 — à mettre en ligne
A36: 35 | B36: 46296 | C36: Jeudi | D36: S01 | E36: Page hors menu | F36: 1 · Piliers B2B | G36: B2B | H36: Page pilier service | L36: Service | M36: Nettoyage verrière et puits de lumière | N36: verrière toit, puits de lumière, verrière atelier | O36: Nettoyage verrière et puits de lumière | ProVitres-64 | P36: Nettoyage verrière et puits de lumière par ProVitres-64, laveur de vitres professionnel basé à Boucau : eau pure, perche 13 m, nacelle. Pays Basque et Sud… | Q36: Nettoyage verrière et puits de lumière — ProVitres-64 | R36: Notre prestation | Pour qui ? | Vitres en hauteur : perche à eau pure jusqu'à 13 m, nacelle si besoin | Sécurité & travail en hauteur | Zones d'intervention | Devis gratuit | T36: Vitres en hauteur : perche à eau pure jusqu'à 13 m, nacelle si besoin | V36: nettoyage-verriere-pays-basque | W36: ="https://www.nettoyage-vitres-bayonne.fr/"&V36 | X36: service-de-nettoyage-professionnels, contact-devis | Y36: Rédigée | AC36: Page générée le 27/09/2026 — à mettre en ligne
A37: 36 | B37: 46296 | C37: Jeudi | D37: S01 | E37: Page hors menu | F37: 1 · Piliers B2B | G37: B2B | H37: Page pilier service | L37: Service | M37: Nettoyage vitres bâtiments publics | N37: collectivités, marchés publics, Chorus Pro, communes | O37: Nettoyage vitres bâtiments publics | ProVitres-64 | P37: Nettoyage vitres bâtiments publics par ProVitres-64, laveur de vitres professionnel basé à Boucau : eau pure, perche 13 m, nacelle. Pays Basque et Sud… | Q37: Nettoyage vitres bâtiments publics — ProVitres-64 | R37: Notre prestation | Pour qui ? | Vitres en hauteur : perche à eau pure jusqu'à 13 m, nacelle si besoin | Sécurité & travail en hauteur | Zones d'intervention | Devis gratuit | T37: Vitres en hauteur : perche à eau pure jusqu'à 13 m, nacelle si besoin | V37: nettoyage-vitres-batiments-publics-pays-basque | W37: ="https://www.nettoyage-vitres-bayonne.fr/"&V37 | X37: service-de-nettoyage-professionnels, contact-devis | Y37: Rédigée | AC37: Page générée le 27/09/2026 — à mettre en ligne
A38: 37 | B38: 46296 | C38: Jeudi | D38: S01 | E38: Page hors menu | F38: 1 · Piliers B2B | G38: B2B | H38: Page pilier service | L38: Service | M38: Contrat entretien vitres entreprise | N38: contrat nettoyage vitres, entretien mensuel, prestataire vitres | O38: Contrat entretien vitres entreprise | ProVitres-64 | P38: Contrat entretien vitres entreprise par ProVitres-64, laveur de vitres professionnel basé à Boucau : eau pure, perche 13 m, nacelle. Pays Basque et Sud… | Q38: Contrat entretien vitres entreprise — ProVitres-64 | R38: Notre prestation | Pour qui ? | Vitres en hauteur : perche à eau pure jusqu'à 13 m, nacelle si besoin | Sécurité & travail en hauteur | Zones d'intervention | Devis gratuit | T38: Vitres en hauteur : perche à eau pure jusqu'à 13 m, nacelle si besoin | V38: contrat-entretien-vitres-entreprise-pays-basque | W38: ="https://www.nettoyage-vitres-bayonne.fr/"&V38 | X38: service-de-nettoyage-professionnels, contact-devis | Y38: Rédigée | AC38: Page générée le 27/09/2026 — à mettre en ligne
A39: 38 | B39: 46296 | C39: Jeudi | D39: S01 | E39: Page hors menu | F39: 1 · Piliers B2B | G39: B2B | H39: Page pilier service | L39: Service | M39: Nettoyage fenêtres professionnel | N39: lavage fenêtres, laveur de fenêtres, nettoyage carreaux | O39: Nettoyage fenêtres professionnel | ProVitres-64 | P39: Nettoyage fenêtres professionnel par ProVitres-64, laveur de vitres professionnel basé à Boucau : eau pure, perche 13 m, nacelle. Pays Basque et Sud… | Q39: Nettoyage fenêtres professionnel — ProVitres-64 | R39: Notre prestation | Pour qui ? | Vitres en hauteur : perche à eau pure jusqu'à 13 m, nacelle si besoin | Sécurité & travail en hauteur | Zones d'intervention | Devis gratuit | T39: Vitres en hauteur : perche à eau pure jusqu'à 13 m, nacelle si besoin | V39: nettoyage-fenetres-pays-basque | W39: ="https://www.nettoyage-vitres-bayonne.fr/"&V39 | X39: service-de-nettoyage-professionnels, contact-devis | Y39: Rédigée | AC39: Page générée le 27/09/2026 — à mettre en ligne
A40: 39 | B40: 46296 | C40: Jeudi | D40: S01 | E40: Article | F40: Articles | G40: B2B | H40: Article collectivités | L40: Mairies & collectivités | M40: nettoyage vitres mairie | O40: Nettoyage des vitres des bâtiments communaux : ce que doit | P40: Nettoyage des vitres des bâtiments communaux : ce que doit prévoir une mairie — les conseils de ProVitres-64, laveur de vitres professionnel au Pays… | Q40: Nettoyage des vitres des bâtiments communaux : ce que doit prévoir une mairie | R40: Introduction | Le problème | Les solutions | Notre méthode | Conclusion + demande de devis | V40: blog-actus/nettoyage-des-vitres-des-batiments-communaux-ce-que-doit-prevoir-une-mairie | W40: ="https://www.nettoyage-vitres-bayonne.fr/"&V40 | X40: blog-actus, contact-devis | Y40: Rédigée | AC40: Page générée le 27/09/2026 — à mettre en ligne
...

Sheet Villes
A1: Rang | B1: Commune (usage SEO) | C1: Nom officiel | D1: Population | E1: Code postal | F1: Département | G1: Intercommunalité | H1: Tranche | I1: Secteur | J1: Angle local | K1: Communes voisines (liens)
A2: 1 | B2: Bayonne | C2: Bayonne | D2: 54306 | E2: 64100 | F2: Pyrénées-Atlantiques (64) | G2: Pays Basque | H2: A · > 10 000 hab. | I2: BAB urbain | J2: la poussière urbaine, le trafic et la pollution grisent vite vitrines, façades et baies vitrées | K2: Tarnos, Boucau, Saint-Pierre-d'Irube
A3: 2 | B3: Anglet | C3: Anglet | D3: 43271 | E3: 64600 | F3: Pyrénées-Atlantiques (64) | G3: Pays Basque | H3: A · > 10 000 hab. | I3: Côte basque | J3: les embruns salés et le sable soulevé par le vent ternissent les vitres face à l'océan en quelques semaines | K3: Biarritz, Hendaye, Saint-Jean-de-Luz
A4: 3 | B4: Biarritz | C4: Biarritz | D4: 26206 | E4: 64200 | F4: Pyrénées-Atlantiques (64) | G4: Pays Basque | H4: A · > 10 000 hab. | I4: Côte basque | J4: les embruns salés et le sable soulevé par le vent ternissent les vitres face à l'océan en quelques semaines | K4: Anglet, Hendaye, Saint-Jean-de-Luz
A5: 4 | B5: Dax | C5: Dax | D5: 22109 | E5: 40100 | F5: Landes (40) | G5: Grand Dax | H5: A · > 10 000 hab. | I5: Dax thermal | J5: hôtels, résidences de curistes et établissements de soins demandent des vitres irréprochables malgré une eau très calcaire | K5: Saint-Paul-lès-Dax
A6: 5 | B6: Hendaye | C6: Hendaye | D6: 18102 | E6: 64700 | F6: Pyrénées-Atlantiques (64) | G6: Pays Basque | H6: A · > 10 000 hab. | I6: Côte basque | J6: les embruns salés et le sable soulevé par le vent ternissent les vitres face à l'océan en quelques semaines | K6: Anglet, Biarritz, Saint-Jean-de-Luz
A7: 6 | B7: Saint-Jean-de-Luz | C7: Saint-Jean-de-Luz | D7: 14857 | E7: 64500 | F7: Pyrénées-Atlantiques (64) | G7: Pays Basque | H7: A · > 10 000 hab. | I7: Côte basque | J7: les embruns salés et le sable soulevé par le vent ternissent les vitres face à l'océan en quelques semaines | K7: Ciboure, Anglet, Biarritz
A8: 7 | B8: Saint-Paul-lès-Dax | C8: Saint-Paul-lès-Dax | D8: 14481 | E8: 40990 | F8: Landes (40) | G8: Grand Dax | H8: A · > 10 000 hab. | I8: Dax thermal | J8: hôtels, résidences de curistes et établissements de soins demandent des vitres irréprochables malgré une eau très calcaire | K8: Dax
A9: 8 | B9: Tarnos | C9: Tarnos | D9: 12957 | E9: 40220 | F9: Landes (40) | G9: Seignanx | H9: A · > 10 000 hab. | I9: BAB urbain | J9: la poussière urbaine, le trafic et la pollution grisent vite vitrines, façades et baies vitrées | K9: Bayonne, Boucau, Saint-Pierre-d'Irube
A10: 9 | B10: Urrugne | C10: Urrugne | D10: 10661 | E10: 64122 | F10: Pyrénées-Atlantiques (64) | G10: Pays Basque | H10: A · > 10 000 hab. | I10: Côte basque | J10: les embruns salés et le sable soulevé par le vent ternissent les vitres face à l'océan en quelques semaines | K10: Anglet, Biarritz, Hendaye
A11: 10 | B11: Capbreton | C11: Capbreton | D11: 9184 | E11: 40130 | F11: Landes (40) | G11: MACS | H11: B · 5 000–10 000 | I11: Côte landaise | J11: le sable, le sel et le pollen de pin forment un film collant sur les baies vitrées des villas et résidences | K11: Soustons, Labenne, Ondres
A12: 11 | B12: Boucau | C12: Boucau | D12: 8968 | E12: 64340 | F12: Pyrénées-Atlantiques (64) | G12: Pays Basque | H12: B · 5 000–10 000 | I12: BAB urbain | J12: la poussière urbaine, le trafic et la pollution grisent vite vitrines, façades et baies vitrées | K12: Bayonne, Tarnos, Saint-Pierre-d'Irube
A13: 12 | B13: Soustons | C13: Soustons | D13: 8701 | E13: 40140 | F13: Landes (40) | G13: MACS | H13: B · 5 000–10 000 | I13: Côte landaise | J13: le sable, le sel et le pollen de pin forment un film collant sur les baies vitrées des villas et résidences | K13: Azur, Capbreton, Labenne
... A234: 233 | B234: L'Hôpital-Saint-Blaise | C234: L'Hôpital-Saint-Blaise | D234: 55 | E234: 64130 | F234: Pyrénées-Atlantiques (64) | G234: Pays Basque | H234: E · < 1 000 | I234: Montagne basque | J234: humidité, mousses et vitrages difficiles d'accès sur les maisons de montagne et bâtiments anciens | K234: Mauléon-Licharre, Chéraute, Viodos-Abense-de-Bas
A236: Source : populations municipales INSEE via le référentiel officiel du découpage administratif (Etalab). Zone = CA Pays Basque + CC Seignanx, MACS, Grand Dax, Orthe et Arrigans.

Sheet Pages existantes
A1: URL existante | B1: Type | C1: Action conseillée
A2: https://www.nettoyage-vitres-bayonne.fr/blog-actus | B2: Page | C2: Garder. Y ajouter des liens vers les nouvelles pages du même thème.
A3: https://www.nettoyage-vitres-bayonne.fr/contact-devis | B3: Page | C3: Garder. Y ajouter des liens vers les nouvelles pages du même thème.
